2025-09-29 23:48:31 - telegram.ext.Updater - ERROR - Error while getting Updates: Conflict: terminated by other getUpdates request; make sure that only one bot instance is running
2025-09-29 23:48:31 - telegram.ext.Application - ERROR - No error handlers are registered, logging exception.
Traceback (most recent call last):
  File "/home/bexultan.kobetay/.local/lib/python3.10/site-packages/telegram/ext/_updater.py", line 640, in _network_loop_retry
    if not await action_cb():
  File "/home/bexultan.kobetay/.local/lib/python3.10/site-packages/telegram/ext/_updater.py", line 345, in polling_action_cb
    raise exc
  File "/home/bexultan.kobetay/.local/lib/python3.10/site-packages/telegram/ext/_updater.py", line 334, in polling_action_cb
    updates = await self.bot.get_updates(
  File "/home/bexultan.kobetay/.local/lib/python3.10/site-packages/telegram/ext/_extbot.py", line 565, in get_updates
    updates = await super().get_updates(
  File "/home/bexultan.kobetay/.local/lib/python3.10/site-packages/telegram/_bot.py", line 519, in decorator
    result = await func(self, *args, **kwargs)  # skipcq: PYL-E1102
  File "/home/bexultan.kobetay/.local/lib/python3.10/site-packages/telegram/_bot.py", line 3562, in get_updates
    await self._post(
  File "/home/bexultan.kobetay/.local/lib/python3.10/site-packages/telegram/_bot.py", line 607, in _post
    return await self._do_post(
  File "/home/bexultan.kobetay/.local/lib/python3.10/site-packages/telegram/ext/_extbot.py", line 347, in _do_post
    return await super()._do_post(
  File "/home/bexultan.kobetay/.local/lib/python3.10/site-packages/telegram/_bot.py", line 635, in _do_post
    return await request.post(
  File "/home/bexultan.kobetay/.local/lib/python3.10/site-packages/telegram/request/_baserequest.py", line 168, in post
    result = await self._request_wrapper(
  File "/home/bexultan.kobetay/.local/lib/python3.10/site-packages/telegram/request/_baserequest.py", line 327, in _request_wrapper
    raise Conflict(message)
telegram.error.Conflict: Conflict: terminated by other getUpdates request; make sure that only one bot instance is running
2025-09-29 23:48:37 - telegram.ext.Updater - ERROR - Error while getting Updates: Conflict: terminated by other getUpdates request; make sure that only one bot instance is running
2025-09-29 23:48:37 - telegram.ext.Application - ERROR - No error handlers are registered, logging exception.
Traceback (most recent call last):
  File "/home/bexultan.kobetay/.local/lib/python3.10/site-packages/telegram/ext/_updater.py", line 640, in _network_loop_retry
    if not await action_cb():
  File "/home/bexultan.kobetay/.local/lib/python3.10/site-packages/telegram/ext/_updater.py", line 345, in polling_action_cb
    raise exc
  File "/home/bexultan.kobetay/.local/lib/python3.10/site-packages/telegram/ext/_updater.py", line 334, in polling_action_cb
    updates = await self.bot.get_updates(
  File "/home/bexultan.kobetay/.local/lib/python3.10/site-packages/telegram/ext/_extbot.py", line 565, in get_updates
    updates = await super().get_updates(
  File "/home/bexultan.kobetay/.local/lib/python3.10/site-packages/telegram/_bot.py", line 519, in decorator
    result = await func(self, *args, **kwargs)  # skipcq: PYL-E1102
  File "/home/bexultan.kobetay/.local/lib/python3.10/site-packages/telegram/_bot.py", line 3562, in get_updates
    await self._post(
  File "/home/bexultan.kobetay/.local/lib/python3.10/site-packages/telegram/_bot.py", line 607, in _post
    return await self._do_post(
  File "/home/bexultan.kobetay/.local/lib/python3.10/site-packages/telegram/ext/_extbot.py", line 347, in _do_post
    return await super()._do_post(
  File "/home/bexultan.kobetay/.local/lib/python3.10/site-packages/telegram/_bot.py", line 635, in _do_post
    return await request.post(
  File "/home/bexultan.kobetay/.local/lib/python3.10/site-packages/telegram/request/_baserequest.py", line 168, in post
    result = await self._request_wrapper(
  File "/home/bexultan.kobetay/.local/lib/python3.10/site-packages/telegram/request/_baserequest.py", line 327, in _request_wrapper
    raise Conflict(message)
telegram.error.Conflict: Conflict: terminated by other getUpdates request; make sure that only one bot instance is running
2025-09-29 23:48:43 - telegram.ext.Updater - ERROR - Error while getting Updates: Conflict: terminated by other getUpdates request; make sure that only one bot instance is running
2025-09-29 23:48:43 - telegram.ext.Application - ERROR - No error handlers are registered, logging exception.
Traceback (most recent call last):
  File "/home/bexultan.kobetay/.local/lib/python3.10/site-packages/telegram/ext/_updater.py", line 640, in _network_loop_retry
    if not await action_cb():
  File "/home/bexultan.kobetay/.local/lib/python3.10/site-packages/telegram/ext/_updater.py", line 345, in polling_action_cb
    raise exc
  File "/home/bexultan.kobetay/.local/lib/python3.10/site-packages/telegram/ext/_updater.py", line 334, in polling_action_cb
    updates = await self.bot.get_updates(
  File "/home/bexultan.kobetay/.local/lib/python3.10/site-packages/telegram/ext/_extbot.py", line 565, in get_updates
    updates = await super().get_updates(
  File "/home/bexultan.kobetay/.local/lib/python3.10/site-packages/telegram/_bot.py", line 519, in decorator
    result = await func(self, *args, **kwargs)  # skipcq: PYL-E1102
  File "/home/bexultan.kobetay/.local/lib/python3.10/site-packages/telegram/_bot.py", line 3562, in get_updates
    await self._post(
  File "/home/bexultan.kobetay/.local/lib/python3.10/site-packages/telegram/_bot.py", line 607, in _post
    return await self._do_post(
  File "/home/bexultan.kobetay/.local/lib/python3.10/site-packages/telegram/ext/_extbot.py", line 347, in _do_post
    return await super()._do_post(
  File "/home/bexultan.kobetay/.local/lib/python3.10/site-packages/telegram/_bot.py", line 635, in _do_post
    return await request.post(
  File "/home/bexultan.kobetay/.local/lib/python3.10/site-packages/telegram/request/_baserequest.py", line 168, in post
    result = await self._request_wrapper(
  File "/home/bexultan.kobetay/.local/lib/python3.10/site-packages/telegram/request/_baserequest.py", line 327, in _request_wrapper
    raise Conflict(message)
telegram.error.Conflict: Conflict: terminated by other getUpdates request; make sure that only one bot instance is running
2025-09-29 23:48:51 - telegram.ext.Updater - ERROR - Error while getting Updates: Conflict: terminated by other getUpdates request; make sure that only one bot instance is running
2025-09-29 23:48:51 - telegram.ext.Application - ERROR - No error handlers are registered, logging exception.
Traceback (most recent call last):
  File "/home/bexultan.kobetay/.local/lib/python3.10/site-packages/telegram/ext/_updater.py", line 640, in _network_loop_retry
    if not await action_cb():
  File "/home/bexultan.kobetay/.local/lib/python3.10/site-packages/telegram/ext/_updater.py", line 345, in polling_action_cb
    raise exc
  File "/home/bexultan.kobetay/.local/lib/python3.10/site-packages/telegram/ext/_updater.py", line 334, in polling_action_cb
    updates = await self.bot.get_updates(
  File "/home/bexultan.kobetay/.local/lib/python3.10/site-packages/telegram/ext/_extbot.py", line 565, in get_updates
    updates = await super().get_updates(
  File "/home/bexultan.kobetay/.local/lib/python3.10/site-packages/telegram/_bot.py", line 519, in decorator
    result = await func(self, *args, **kwargs)  # skipcq: PYL-E1102
  File "/home/bexultan.kobetay/.local/lib/python3.10/site-packages/telegram/_bot.py", line 3562, in get_updates
    await self._post(
  File "/home/bexultan.kobetay/.local/lib/python3.10/site-packages/telegram/_bot.py", line 607, in _post
    return await self._do_post(
  File "/home/bexultan.kobetay/.local/lib/python3.10/site-packages/telegram/ext/_extbot.py", line 347, in _do_post
    return await super()._do_post(
  File "/home/bexultan.kobetay/.local/lib/python3.10/site-packages/telegram/_bot.py", line 635, in _do_post
    return await request.post(
  File "/home/bexultan.kobetay/.local/lib/python3.10/site-packages/telegram/request/_baserequest.py", line 168, in post
    result = await self._request_wrapper(
  File "/home/bexultan.kobetay/.local/lib/python3.10/site-packages/telegram/request/_baserequest.py", line 327, in _request_wrapper
    raise Conflict(message)
telegram.error.Conflict: Conflict: terminated by other getUpdates request; make sure that only one bot instance is running
2025-09-29 23:48:58 - telegram.ext.Updater - ERROR - Error while getting Updates: Conflict: terminated by other getUpdates request; make sure that only one bot instance is running
2025-09-29 23:48:58 - telegram.ext.Application - ERROR - No error handlers are registered, logging exception.
Traceback (most recent call last):
  File "/home/bexultan.kobetay/.local/lib/python3.10/site-packages/telegram/ext/_updater.py", line 640, in _network_loop_retry
    if not await action_cb():
  File "/home/bexultan.kobetay/.local/lib/python3.10/site-packages/telegram/ext/_updater.py", line 345, in polling_action_cb
    raise exc
  File "/home/bexultan.kobetay/.local/lib/python3.10/site-packages/telegram/ext/_updater.py", line 334, in polling_action_cb
    updates = await self.bot.get_updates(
  File "/home/bexultan.kobetay/.local/lib/python3.10/site-packages/telegram/ext/_extbot.py", line 565, in get_updates
    updates = await super().get_updates(
  File "/home/bexultan.kobetay/.local/lib/python3.10/site-packages/telegram/_bot.py", line 519, in decorator
    result = await func(self, *args, **kwargs)  # skipcq: PYL-E1102
  File "/home/bexultan.kobetay/.local/lib/python3.10/site-packages/telegram/_bot.py", line 3562, in get_updates
    await self._post(
  File "/home/bexultan.kobetay/.local/lib/python3.10/site-packages/telegram/_bot.py", line 607, in _post
    return await self._do_post(
  File "/home/bexultan.kobetay/.local/lib/python3.10/site-packages/telegram/ext/_extbot.py", line 347, in _do_post
    return await super()._do_post(
  File "/home/bexultan.kobetay/.local/lib/python3.10/site-packages/telegram/_bot.py", line 635, in _do_post
    return await request.post(
  File "/home/bexultan.kobetay/.local/lib/python3.10/site-packages/telegram/request/_baserequest.py", line 168, in post
    result = await self._request_wrapper(
  File "/home/bexultan.kobetay/.local/lib/python3.10/site-packages/telegram/request/_baserequest.py", line 327, in _request_wrapper
    raise Conflict(message)
telegram.error.Conflict: Conflict: terminated by other getUpdates request; make sure that only one bot instance is running
2025-09-29 23:49:08 - telegram.ext.Updater - ERROR - Error while getting Updates: Conflict: terminated by other getUpdates request; make sure that only one bot instance is running
2025-09-29 23:49:08 - telegram.ext.Application - ERROR - No error handlers are registered, logging exception.
Traceback (most recent call last):
  File "/home/bexultan.kobetay/.local/lib/python3.10/site-packages/telegram/ext/_updater.py", line 640, in _network_loop_retry
    if not await action_cb():
  File "/home/bexultan.kobetay/.local/lib/python3.10/site-packages/telegram/ext/_updater.py", line 345, in polling_action_cb
    raise exc
  File "/home/bexultan.kobetay/.local/lib/python3.10/site-packages/telegram/ext/_updater.py", line 334, in polling_action_cb
    updates = await self.bot.get_updates(
  File "/home/bexultan.kobetay/.local/lib/python3.10/site-packages/telegram/ext/_extbot.py", line 565, in get_updates
    updates = await super().get_updates(
  File "/home/bexultan.kobetay/.local/lib/python3.10/site-packages/telegram/_bot.py", line 519, in decorator
    result = await func(self, *args, **kwargs)  # skipcq: PYL-E1102
  File "/home/bexultan.kobetay/.local/lib/python3.10/site-packages/telegram/_bot.py", line 3562, in get_updates
    await self._post(
  File "/home/bexultan.kobetay/.local/lib/python3.10/site-packages/telegram/_bot.py", line 607, in _post
    return await self._do_post(
  File "/home/bexultan.kobetay/.local/lib/python3.10/site-packages/telegram/ext/_extbot.py", line 347, in _do_post
    return await super()._do_post(
  File "/home/bexultan.kobetay/.local/lib/python3.10/site-packages/telegram/_bot.py", line 635, in _do_post
    return await request.post(
  File "/home/bexultan.kobetay/.local/lib/python3.10/site-packages/telegram/request/_baserequest.py", line 168, in post
    result = await self._request_wrapper(
  File "/home/bexultan.kobetay/.local/lib/python3.10/site-packages/telegram/request/_baserequest.py", line 327, in _request_wrapper
    raise Conflict(message)
telegram.error.Conflict: Conflict: terminated by other getUpdates request; make sure that only one bot instance is running
2025-09-29 23:51:40 - telegram.ext.Application - ERROR - No error handlers are registered, logging exception.
Traceback (most recent call last):
  File "/home/bexultan.kobetay/.local/lib/python3.10/site-packages/telegram/ext/_application.py", line 1195, in process_update
    await coroutine
  File "/home/bexultan.kobetay/.local/lib/python3.10/site-packages/telegram/ext/_basehandler.py", line 153, in handle_update
    return await self.callback(update, context)
  File "/home/bexultan.kobetay/KENMART/The_gap_2/src/handlers/navigation_handlers.py", line 35, in back_to_previous_menu
    await handle_shift_choice_menu(update, context)
  File "/home/bexultan.kobetay/KENMART/The_gap_2/src/handlers/navigation_handlers.py", line 103, in handle_shift_choice_menu
    await query.edit_message_text(f"Вы выбрали смену: {shift}. Теперь выберите роль:", reply_markup=reply_markup)
  File "/home/bexultan.kobetay/.local/lib/python3.10/site-packages/telegram/_callbackquery.py", line 241, in edit_message_text
    return await self.message.edit_text(
  File "/home/bexultan.kobetay/.local/lib/python3.10/site-packages/telegram/_message.py", line 2537, in edit_text
    return await self.get_bot().edit_message_text(
  File "/home/bexultan.kobetay/.local/lib/python3.10/site-packages/telegram/ext/_extbot.py", line 1480, in edit_message_text
    return await super().edit_message_text(
  File "/home/bexultan.kobetay/.local/lib/python3.10/site-packages/telegram/_bot.py", line 519, in decorator
    result = await func(self, *args, **kwargs)  # skipcq: PYL-E1102
  File "/home/bexultan.kobetay/.local/lib/python3.10/site-packages/telegram/_bot.py", line 3282, in edit_message_text
    return await self._send_message(
  File "/home/bexultan.kobetay/.local/lib/python3.10/site-packages/telegram/ext/_extbot.py", line 529, in _send_message
    result = await super()._send_message(
  File "/home/bexultan.kobetay/.local/lib/python3.10/site-packages/telegram/_bot.py", line 697, in _send_message
    result = await self._post(
  File "/home/bexultan.kobetay/.local/lib/python3.10/site-packages/telegram/_bot.py", line 607, in _post
    return await self._do_post(
  File "/home/bexultan.kobetay/.local/lib/python3.10/site-packages/telegram/ext/_extbot.py", line 347, in _do_post
    return await super()._do_post(
  File "/home/bexultan.kobetay/.local/lib/python3.10/site-packages/telegram/_bot.py", line 635, in _do_post
    return await request.post(
  File "/home/bexultan.kobetay/.local/lib/python3.10/site-packages/telegram/request/_baserequest.py", line 168, in post
    result = await self._request_wrapper(
  File "/home/bexultan.kobetay/.local/lib/python3.10/site-packages/telegram/request/_baserequest.py", line 325, in _request_wrapper
    raise BadRequest(message)
telegram.error.BadRequest: Message is not modified: specified new message content and reply markup are exactly the same as a current content and reply markup of the message
2025-09-29 23:51:42 - telegram.ext.Application - ERROR - No error handlers are registered, logging exception.
Traceback (most recent call last):
  File "/home/bexultan.kobetay/.local/lib/python3.10/site-packages/telegram/ext/_application.py", line 1195, in process_update
    await coroutine
  File "/home/bexultan.kobetay/.local/lib/python3.10/site-packages/telegram/ext/_basehandler.py", line 153, in handle_update
    return await self.callback(update, context)
  File "/home/bexultan.kobetay/KENMART/The_gap_2/src/handlers/navigation_handlers.py", line 35, in back_to_previous_menu
    await handle_shift_choice_menu(update, context)
  File "/home/bexultan.kobetay/KENMART/The_gap_2/src/handlers/navigation_handlers.py", line 103, in handle_shift_choice_menu
    await query.edit_message_text(f"Вы выбрали смену: {shift}. Теперь выберите роль:", reply_markup=reply_markup)
  File "/home/bexultan.kobetay/.local/lib/python3.10/site-packages/telegram/_callbackquery.py", line 241, in edit_message_text
    return await self.message.edit_text(
  File "/home/bexultan.kobetay/.local/lib/python3.10/site-packages/telegram/_message.py", line 2537, in edit_text
    return await self.get_bot().edit_message_text(
  File "/home/bexultan.kobetay/.local/lib/python3.10/site-packages/telegram/ext/_extbot.py", line 1480, in edit_message_text
    return await super().edit_message_text(
  File "/home/bexultan.kobetay/.local/lib/python3.10/site-packages/telegram/_bot.py", line 519, in decorator
    result = await func(self, *args, **kwargs)  # skipcq: PYL-E1102
  File "/home/bexultan.kobetay/.local/lib/python3.10/site-packages/telegram/_bot.py", line 3282, in edit_message_text
    return await self._send_message(
  File "/home/bexultan.kobetay/.local/lib/python3.10/site-packages/telegram/ext/_extbot.py", line 529, in _send_message
    result = await super()._send_message(
  File "/home/bexultan.kobetay/.local/lib/python3.10/site-packages/telegram/_bot.py", line 697, in _send_message
    result = await self._post(
  File "/home/bexultan.kobetay/.local/lib/python3.10/site-packages/telegram/_bot.py", line 607, in _post
    return await self._do_post(
  File "/home/bexultan.kobetay/.local/lib/python3.10/site-packages/telegram/ext/_extbot.py", line 347, in _do_post
    return await super()._do_post(
  File "/home/bexultan.kobetay/.local/lib/python3.10/site-packages/telegram/_bot.py", line 635, in _do_post
    return await request.post(
  File "/home/bexultan.kobetay/.local/lib/python3.10/site-packages/telegram/request/_baserequest.py", line 168, in post
    result = await self._request_wrapper(
  File "/home/bexultan.kobetay/.local/lib/python3.10/site-packages/telegram/request/_baserequest.py", line 325, in _request_wrapper
    raise BadRequest(message)
telegram.error.BadRequest: Message is not modified: specified new message content and reply markup are exactly the same as a current content and reply markup of the message
2025-09-29 23:51:52 - telegram.ext.Application - ERROR - No error handlers are registered, logging exception.
Traceback (most recent call last):
  File "/home/bexultan.kobetay/.local/lib/python3.10/site-packages/telegram/ext/_application.py", line 1195, in process_update
    await coroutine
  File "/home/bexultan.kobetay/.local/lib/python3.10/site-packages/telegram/ext/_basehandler.py", line 153, in handle_update
    return await self.callback(update, context)
  File "/home/bexultan.kobetay/KENMART/The_gap_2/src/handlers/navigation_handlers.py", line 35, in back_to_previous_menu
    await handle_shift_choice_menu(update, context)
  File "/home/bexultan.kobetay/KENMART/The_gap_2/src/handlers/navigation_handlers.py", line 103, in handle_shift_choice_menu
    await query.edit_message_text(f"Вы выбрали смену: {shift}. Теперь выберите роль:", reply_markup=reply_markup)
  File "/home/bexultan.kobetay/.local/lib/python3.10/site-packages/telegram/_callbackquery.py", line 241, in edit_message_text
    return await self.message.edit_text(
  File "/home/bexultan.kobetay/.local/lib/python3.10/site-packages/telegram/_message.py", line 2537, in edit_text
    return await self.get_bot().edit_message_text(
  File "/home/bexultan.kobetay/.local/lib/python3.10/site-packages/telegram/ext/_extbot.py", line 1480, in edit_message_text
    return await super().edit_message_text(
  File "/home/bexultan.kobetay/.local/lib/python3.10/site-packages/telegram/_bot.py", line 519, in decorator
    result = await func(self, *args, **kwargs)  # skipcq: PYL-E1102
  File "/home/bexultan.kobetay/.local/lib/python3.10/site-packages/telegram/_bot.py", line 3282, in edit_message_text
    return await self._send_message(
  File "/home/bexultan.kobetay/.local/lib/python3.10/site-packages/telegram/ext/_extbot.py", line 529, in _send_message
    result = await super()._send_message(
  File "/home/bexultan.kobetay/.local/lib/python3.10/site-packages/telegram/_bot.py", line 697, in _send_message
    result = await self._post(
  File "/home/bexultan.kobetay/.local/lib/python3.10/site-packages/telegram/_bot.py", line 607, in _post
    return await self._do_post(
  File "/home/bexultan.kobetay/.local/lib/python3.10/site-packages/telegram/ext/_extbot.py", line 347, in _do_post
    return await super()._do_post(
  File "/home/bexultan.kobetay/.local/lib/python3.10/site-packages/telegram/_bot.py", line 635, in _do_post
    return await request.post(
  File "/home/bexultan.kobetay/.local/lib/python3.10/site-packages/telegram/request/_baserequest.py", line 168, in post
    result = await self._request_wrapper(
  File "/home/bexultan.kobetay/.local/lib/python3.10/site-packages/telegram/request/_baserequest.py", line 325, in _request_wrapper
    raise BadRequest(message)
telegram.error.BadRequest: Message is not modified: specified new message content and reply markup are exactly the same as a current content and reply markup of the message
2025-09-30 06:13:10 - telegram.ext.Updater - ERROR - Error while getting Updates: Bad Gateway
2025-09-30 06:13:10 - telegram.ext.Application - ERROR - No error handlers are registered, logging exception.
Traceback (most recent call last):
  File "/home/bexultan.kobetay/.local/lib/python3.10/site-packages/telegram/ext/_updater.py", line 640, in _network_loop_retry
    if not await action_cb():
  File "/home/bexultan.kobetay/.local/lib/python3.10/site-packages/telegram/ext/_updater.py", line 345, in polling_action_cb
    raise exc
  File "/home/bexultan.kobetay/.local/lib/python3.10/site-packages/telegram/ext/_updater.py", line 334, in polling_action_cb
    updates = await self.bot.get_updates(
  File "/home/bexultan.kobetay/.local/lib/python3.10/site-packages/telegram/ext/_extbot.py", line 565, in get_updates
    updates = await super().get_updates(
  File "/home/bexultan.kobetay/.local/lib/python3.10/site-packages/telegram/_bot.py", line 519, in decorator
    result = await func(self, *args, **kwargs)  # skipcq: PYL-E1102
  File "/home/bexultan.kobetay/.local/lib/python3.10/site-packages/telegram/_bot.py", line 3562, in get_updates
    await self._post(
  File "/home/bexultan.kobetay/.local/lib/python3.10/site-packages/telegram/_bot.py", line 607, in _post
    return await self._do_post(
  File "/home/bexultan.kobetay/.local/lib/python3.10/site-packages/telegram/ext/_extbot.py", line 347, in _do_post
    return await super()._do_post(
  File "/home/bexultan.kobetay/.local/lib/python3.10/site-packages/telegram/_bot.py", line 635, in _do_post
    return await request.post(
  File "/home/bexultan.kobetay/.local/lib/python3.10/site-packages/telegram/request/_baserequest.py", line 168, in post
    result = await self._request_wrapper(
  File "/home/bexultan.kobetay/.local/lib/python3.10/site-packages/telegram/request/_baserequest.py", line 329, in _request_wrapper
    raise NetworkError(description or "Bad Gateway")
telegram.error.NetworkError: Bad Gateway
2025-09-30 08:42:15 - telegram.ext.Application - ERROR - No error handlers are registered, logging exception.
Traceback (most recent call last):
  File "/home/bexultan.kobetay/KENMART/The_gap_2/src/handlers/task_handlers/special_task_completion.py", line 66, in complete_special_task_directly
    if frozen_task_id in frozen_tasks_info and 'original_start_time' in frozen_tasks_info[frozen_task_id]:
UnboundLocalError: local variable 'frozen_tasks_info' referenced before assignment

During handling of the above exception, another exception occurred:

Traceback (most recent call last):
  File "/home/bexultan.kobetay/.local/lib/python3.10/site-packages/telegram/ext/_application.py", line 1195, in process_update
    await coroutine
  File "/home/bexultan.kobetay/.local/lib/python3.10/site-packages/telegram/ext/_basehandler.py", line 153, in handle_update
    return await self.callback(update, context)
  File "/home/bexultan.kobetay/KENMART/The_gap_2/src/handlers/task_handlers/task_execution.py", line 358, in complete_the_task
    await complete_special_task_directly(fake_update, context, task)
  File "/home/bexultan.kobetay/KENMART/The_gap_2/src/handlers/task_handlers/special_task_completion.py", line 208, in complete_special_task_directly
    await query.edit_message_text("⚠️ Ошибка при завершении спец-задания. Попробуйте позже.")
AttributeError: 'FakeCallbackQuery' object has no attribute 'edit_message_text'
2025-09-30 09:29:00 - telegram.ext.Application - ERROR - No error handlers are registered, logging exception.
Traceback (most recent call last):
  File "/home/bexultan.kobetay/KENMART/The_gap_2/src/handlers/task_handlers/special_task_completion.py", line 66, in complete_special_task_directly
    if frozen_task_id in frozen_tasks_info and 'original_start_time' in frozen_tasks_info[frozen_task_id]:
UnboundLocalError: local variable 'frozen_tasks_info' referenced before assignment

During handling of the above exception, another exception occurred:

Traceback (most recent call last):
  File "/home/bexultan.kobetay/.local/lib/python3.10/site-packages/telegram/ext/_application.py", line 1195, in process_update
    await coroutine
  File "/home/bexultan.kobetay/.local/lib/python3.10/site-packages/telegram/ext/_basehandler.py", line 153, in handle_update
    return await self.callback(update, context)
  File "/home/bexultan.kobetay/KENMART/The_gap_2/src/handlers/task_handlers/task_execution.py", line 358, in complete_the_task
    await complete_special_task_directly(fake_update, context, task)
  File "/home/bexultan.kobetay/KENMART/The_gap_2/src/handlers/task_handlers/special_task_completion.py", line 208, in complete_special_task_directly
    await query.edit_message_text("⚠️ Ошибка при завершении спец-задания. Попробуйте позже.")
AttributeError: 'FakeCallbackQuery' object has no attribute 'edit_message_text'
