2025-09-25 20:17:29 - telegram.ext.Application - ERROR - No error handlers are registered, logging exception.
Traceback (most recent call last):
  File "C:\Users\Alpha\AppData\Local\Programs\Python\Python313\Lib\site-packages\telegram\ext\_application.py", line 1311, in process_update
    await coroutine
  File "C:\Users\Alpha\AppData\Local\Programs\Python\Python313\Lib\site-packages\telegram\ext\_handlers\basehandler.py", line 158, in handle_update
    return await self.callback(update, context)
           ^^^^^^^^^^^^^^^^^^^^^^^^^^^^^^^^^^^^
  File "G:\FOR ALL BOTS\The_gap\src\handlers\task_handlers\task_execution.py", line 205, in complete_the_task
    await complete_task_inline(update, context)
  File "G:\FOR ALL BOTS\The_gap\src\handlers\task_handlers\task_execution.py", line 15, in complete_task_inline
    await query.answer()
          ^^^^^^^^^^^^
AttributeError: 'NoneType' object has no attribute 'answer'
2025-09-25 20:36:33 - asyncio - ERROR - Task was destroyed but it is pending!
task: <Task pending name='Task-22' coro=<update_timer() running at G:\FOR ALL BOTS\The_gap\src\handlers\task_handlers\task_timer.py:89> wait_for=<Future pending cb=[Task.task_wakeup()]>>
2025-09-25 20:40:16 - telegram.ext.Application - ERROR - No error handlers are registered, logging exception.
Traceback (most recent call last):
  File "C:\Users\Alpha\AppData\Local\Programs\Python\Python313\Lib\site-packages\telegram\ext\_application.py", line 1311, in process_update
    await coroutine
  File "C:\Users\Alpha\AppData\Local\Programs\Python\Python313\Lib\site-packages\telegram\ext\_handlers\basehandler.py", line 158, in handle_update
    return await self.callback(update, context)
           ^^^^^^^^^^^^^^^^^^^^^^^^^^^^^^^^^^^^
  File "G:\FOR ALL BOTS\The_gap\src\handlers\task_handlers\task_execution.py", line 473, in complete_the_task
    update.callback_query = fake_query
    ^^^^^^^^^^^^^^^^^^^^^
  File "C:\Users\Alpha\AppData\Local\Programs\Python\Python313\Lib\site-packages\telegram\_telegramobject.py", line 159, in __setattr__
    raise AttributeError(
        f"Attribute `{key}` of class `{self.__class__.__name__}` can't be set!"
    )
AttributeError: Attribute `callback_query` of class `Update` can't be set!
2025-09-25 21:05:24 - asyncio - ERROR - Task was destroyed but it is pending!
task: <Task pending name='Task-20' coro=<update_timer() running at G:\FOR ALL BOTS\The_gap\src\handlers\task_handlers\task_timer.py:89> wait_for=<Future pending cb=[Task.task_wakeup()]>>
2025-09-25 22:11:22 - apscheduler.executors.default - ERROR - Job "schedule_tasks_from_rules (trigger: interval[0:00:05], next run at: 2025-09-25 17:11:18 UTC)" raised an exception
Traceback (most recent call last):
  File "C:\Users\Alpha\AppData\Local\Programs\Python\Python313\Lib\site-packages\apscheduler\executors\base.py", line 181, in run_coroutine_job
    retval = await job.func(*job.args, **job.kwargs)
             ^^^^^^^^^^^^^^^^^^^^^^^^^^^^^^^^^^^^^^^
  File "C:\Users\Alpha\AppData\Local\Programs\Python\Python313\Lib\site-packages\telegram\ext\_jobqueue.py", line 245, in job_callback
    await job.run(job_queue.application)
  File "C:\Users\Alpha\AppData\Local\Programs\Python\Python313\Lib\site-packages\telegram\ext\_jobqueue.py", line 980, in run
    await asyncio.shield(self._run(application))
  File "C:\Users\Alpha\AppData\Local\Programs\Python\Python313\Lib\site-packages\telegram\ext\_application.py", line 1057, in __run
    loop.run_forever()
    ~~~~~~~~~~~~~~~~^^
  File "C:\Users\Alpha\AppData\Local\Programs\Python\Python313\Lib\asyncio\base_events.py", line 683, in run_forever
    self._run_once()
    ~~~~~~~~~~~~~~^^
  File "C:\Users\Alpha\AppData\Local\Programs\Python\Python313\Lib\asyncio\base_events.py", line 2050, in _run_once
    handle._run()
    ~~~~~~~~~~~^^
  File "C:\Users\Alpha\AppData\Local\Programs\Python\Python313\Lib\asyncio\events.py", line 89, in _run
    self._context.run(self._callback, *self._args)
    ~~~~~~~~~~~~~~~~~^^^^^^^^^^^^^^^^^^^^^^^^^^^^^
  File "C:\Users\Alpha\AppData\Local\Programs\Python\Python313\Lib\site-packages\telegram\ext\_jobqueue.py", line 997, in _run
    await self.callback(context)
  File "G:\FOR ALL BOTS\The_gap\src\scheduler\task_scheduler.py", line 91, in schedule_tasks_from_rules
    duplicates_df = SQL.sql_select('wms', f"""
        SELECT COUNT(*) as task_count
    ...<7 lines>...
        AND merchant_code = '{MERCHANT_ID}'
    """)
  File "G:\FOR ALL BOTS\The_gap\kidou_s.py", line 169, in sql_select
    cursor.execute(select_request)
    ~~~~~~~~~~~~~~^^^^^^^^^^^^^^^^
  File "C:\Users\Alpha\AppData\Local\Programs\Python\Python313\Lib\encodings\utf_8.py", line 15, in decode
    def decode(input, errors='strict'):
    
KeyboardInterrupt
2025-09-25 22:32:47 - telegram.ext.Application - ERROR - No error handlers are registered, logging exception.
Traceback (most recent call last):
  File "C:\Users\Alpha\AppData\Local\Programs\Python\Python313\Lib\site-packages\telegram\ext\_application.py", line 1311, in process_update
    await coroutine
  File "C:\Users\Alpha\AppData\Local\Programs\Python\Python313\Lib\site-packages\telegram\ext\_handlers\basehandler.py", line 158, in handle_update
    return await self.callback(update, context)
           ^^^^^^^^^^^^^^^^^^^^^^^^^^^^^^^^^^^^
  File "G:\FOR ALL BOTS\The_gap\src\handlers\task_handlers\task_execution.py", line 38, in complete_task_inline
    if task_df.empty:
       ^^^^^^^^^^^^^
AttributeError: 'AttributeError' object has no attribute 'empty'
2025-09-25 22:32:47 - telegram.ext.Application - ERROR - No error handlers are registered, logging exception.
Traceback (most recent call last):
  File "C:\Users\Alpha\AppData\Local\Programs\Python\Python313\Lib\site-packages\telegram\ext\_application.py", line 1311, in process_update
    await coroutine
  File "C:\Users\Alpha\AppData\Local\Programs\Python\Python313\Lib\site-packages\telegram\ext\_handlers\basehandler.py", line 158, in handle_update
    return await self.callback(update, context)
           ^^^^^^^^^^^^^^^^^^^^^^^^^^^^^^^^^^^^
  File "G:\FOR ALL BOTS\The_gap\src\handlers\task_handlers\task_execution.py", line 38, in complete_task_inline
    if task_df.empty:
       ^^^^^^^^^^^^^
AttributeError: 'AttributeError' object has no attribute 'empty'
