2025-10-09 15:21:25 - telegram.ext.Application - ERROR - No error handlers are registered, logging exception.
Traceback (most recent call last):
  File "C:\Users\Alpha\AppData\Local\Programs\Python\Python313\Lib\site-packages\telegram\ext\_utils\networkloop.py", line 134, in network_retry_loop
    await do_action()
  File "C:\Users\Alpha\AppData\Local\Programs\Python\Python313\Lib\site-packages\telegram\ext\_utils\networkloop.py", line 127, in do_action
    action_cb_task.result()
    ~~~~~~~~~~~~~~~~~~~~~^^
  File "C:\Users\Alpha\AppData\Local\Programs\Python\Python313\Lib\site-packages\telegram\ext\_updater.py", line 340, in polling_action_cb
    updates = await self.bot.get_updates(
              ^^^^^^^^^^^^^^^^^^^^^^^^^^^
    ...<3 lines>...
    )
    ^
  File "C:\Users\Alpha\AppData\Local\Programs\Python\Python313\Lib\site-packages\telegram\ext\_extbot.py", line 676, in get_updates
    updates = await super().get_updates(
              ^^^^^^^^^^^^^^^^^^^^^^^^^^
    ...<9 lines>...
    )
    ^
  File "C:\Users\Alpha\AppData\Local\Programs\Python\Python313\Lib\site-packages\telegram\_bot.py", line 4780, in get_updates
    await self._post(
    ^^^^^^^^^^^^^^^^^
    ...<7 lines>...
    ),
    ^
  File "C:\Users\Alpha\AppData\Local\Programs\Python\Python313\Lib\site-packages\telegram\_bot.py", line 703, in _post
    return await self._do_post(
           ^^^^^^^^^^^^^^^^^^^^
    ...<6 lines>...
    )
    ^
  File "C:\Users\Alpha\AppData\Local\Programs\Python\Python313\Lib\site-packages\telegram\ext\_extbot.py", line 372, in _do_post
    return await super()._do_post(
           ^^^^^^^^^^^^^^^^^^^^^^^
    ...<6 lines>...
    )
    ^
  File "C:\Users\Alpha\AppData\Local\Programs\Python\Python313\Lib\site-packages\telegram\_bot.py", line 732, in _do_post
    result = await request.post(
             ^^^^^^^^^^^^^^^^^^^
    ...<6 lines>...
    )
    ^
  File "C:\Users\Alpha\AppData\Local\Programs\Python\Python313\Lib\site-packages\telegram\request\_baserequest.py", line 198, in post
    result = await self._request_wrapper(
             ^^^^^^^^^^^^^^^^^^^^^^^^^^^^
    ...<7 lines>...
    )
    ^
  File "C:\Users\Alpha\AppData\Local\Programs\Python\Python313\Lib\site-packages\telegram\request\_baserequest.py", line 375, in _request_wrapper
    raise exception
telegram.error.Conflict: Conflict: terminated by other getUpdates request; make sure that only one bot instance is running
2025-10-09 15:21:29 - telegram.ext.Application - ERROR - No error handlers are registered, logging exception.
Traceback (most recent call last):
  File "C:\Users\Alpha\AppData\Local\Programs\Python\Python313\Lib\site-packages\telegram\ext\_utils\networkloop.py", line 134, in network_retry_loop
    await do_action()
  File "C:\Users\Alpha\AppData\Local\Programs\Python\Python313\Lib\site-packages\telegram\ext\_utils\networkloop.py", line 127, in do_action
    action_cb_task.result()
    ~~~~~~~~~~~~~~~~~~~~~^^
  File "C:\Users\Alpha\AppData\Local\Programs\Python\Python313\Lib\site-packages\telegram\ext\_updater.py", line 340, in polling_action_cb
    updates = await self.bot.get_updates(
              ^^^^^^^^^^^^^^^^^^^^^^^^^^^
    ...<3 lines>...
    )
    ^
  File "C:\Users\Alpha\AppData\Local\Programs\Python\Python313\Lib\site-packages\telegram\ext\_extbot.py", line 676, in get_updates
    updates = await super().get_updates(
              ^^^^^^^^^^^^^^^^^^^^^^^^^^
    ...<9 lines>...
    )
    ^
  File "C:\Users\Alpha\AppData\Local\Programs\Python\Python313\Lib\site-packages\telegram\_bot.py", line 4780, in get_updates
    await self._post(
    ^^^^^^^^^^^^^^^^^
    ...<7 lines>...
    ),
    ^
  File "C:\Users\Alpha\AppData\Local\Programs\Python\Python313\Lib\site-packages\telegram\_bot.py", line 703, in _post
    return await self._do_post(
           ^^^^^^^^^^^^^^^^^^^^
    ...<6 lines>...
    )
    ^
  File "C:\Users\Alpha\AppData\Local\Programs\Python\Python313\Lib\site-packages\telegram\ext\_extbot.py", line 372, in _do_post
    return await super()._do_post(
           ^^^^^^^^^^^^^^^^^^^^^^^
    ...<6 lines>...
    )
    ^
  File "C:\Users\Alpha\AppData\Local\Programs\Python\Python313\Lib\site-packages\telegram\_bot.py", line 732, in _do_post
    result = await request.post(
             ^^^^^^^^^^^^^^^^^^^
    ...<6 lines>...
    )
    ^
  File "C:\Users\Alpha\AppData\Local\Programs\Python\Python313\Lib\site-packages\telegram\request\_baserequest.py", line 198, in post
    result = await self._request_wrapper(
             ^^^^^^^^^^^^^^^^^^^^^^^^^^^^
    ...<7 lines>...
    )
    ^
  File "C:\Users\Alpha\AppData\Local\Programs\Python\Python313\Lib\site-packages\telegram\request\_baserequest.py", line 375, in _request_wrapper
    raise exception
telegram.error.Conflict: Conflict: terminated by other getUpdates request; make sure that only one bot instance is running
2025-10-09 15:21:30 - telegram.ext.Application - ERROR - No error handlers are registered, logging exception.
Traceback (most recent call last):
  File "C:\Users\Alpha\AppData\Local\Programs\Python\Python313\Lib\site-packages\telegram\ext\_utils\networkloop.py", line 134, in network_retry_loop
    await do_action()
  File "C:\Users\Alpha\AppData\Local\Programs\Python\Python313\Lib\site-packages\telegram\ext\_utils\networkloop.py", line 127, in do_action
    action_cb_task.result()
    ~~~~~~~~~~~~~~~~~~~~~^^
  File "C:\Users\Alpha\AppData\Local\Programs\Python\Python313\Lib\site-packages\telegram\ext\_updater.py", line 340, in polling_action_cb
    updates = await self.bot.get_updates(
              ^^^^^^^^^^^^^^^^^^^^^^^^^^^
    ...<3 lines>...
    )
    ^
  File "C:\Users\Alpha\AppData\Local\Programs\Python\Python313\Lib\site-packages\telegram\ext\_extbot.py", line 676, in get_updates
    updates = await super().get_updates(
              ^^^^^^^^^^^^^^^^^^^^^^^^^^
    ...<9 lines>...
    )
    ^
  File "C:\Users\Alpha\AppData\Local\Programs\Python\Python313\Lib\site-packages\telegram\_bot.py", line 4780, in get_updates
    await self._post(
    ^^^^^^^^^^^^^^^^^
    ...<7 lines>...
    ),
    ^
  File "C:\Users\Alpha\AppData\Local\Programs\Python\Python313\Lib\site-packages\telegram\_bot.py", line 703, in _post
    return await self._do_post(
           ^^^^^^^^^^^^^^^^^^^^
    ...<6 lines>...
    )
    ^
  File "C:\Users\Alpha\AppData\Local\Programs\Python\Python313\Lib\site-packages\telegram\ext\_extbot.py", line 372, in _do_post
    return await super()._do_post(
           ^^^^^^^^^^^^^^^^^^^^^^^
    ...<6 lines>...
    )
    ^
  File "C:\Users\Alpha\AppData\Local\Programs\Python\Python313\Lib\site-packages\telegram\_bot.py", line 732, in _do_post
    result = await request.post(
             ^^^^^^^^^^^^^^^^^^^
    ...<6 lines>...
    )
    ^
  File "C:\Users\Alpha\AppData\Local\Programs\Python\Python313\Lib\site-packages\telegram\request\_baserequest.py", line 198, in post
    result = await self._request_wrapper(
             ^^^^^^^^^^^^^^^^^^^^^^^^^^^^
    ...<7 lines>...
    )
    ^
  File "C:\Users\Alpha\AppData\Local\Programs\Python\Python313\Lib\site-packages\telegram\request\_baserequest.py", line 375, in _request_wrapper
    raise exception
telegram.error.Conflict: Conflict: terminated by other getUpdates request; make sure that only one bot instance is running
2025-10-09 15:21:36 - telegram.ext.Application - ERROR - No error handlers are registered, logging exception.
Traceback (most recent call last):
  File "C:\Users\Alpha\AppData\Local\Programs\Python\Python313\Lib\site-packages\telegram\ext\_utils\networkloop.py", line 134, in network_retry_loop
    await do_action()
  File "C:\Users\Alpha\AppData\Local\Programs\Python\Python313\Lib\site-packages\telegram\ext\_utils\networkloop.py", line 127, in do_action
    action_cb_task.result()
    ~~~~~~~~~~~~~~~~~~~~~^^
  File "C:\Users\Alpha\AppData\Local\Programs\Python\Python313\Lib\site-packages\telegram\ext\_updater.py", line 340, in polling_action_cb
    updates = await self.bot.get_updates(
              ^^^^^^^^^^^^^^^^^^^^^^^^^^^
    ...<3 lines>...
    )
    ^
  File "C:\Users\Alpha\AppData\Local\Programs\Python\Python313\Lib\site-packages\telegram\ext\_extbot.py", line 676, in get_updates
    updates = await super().get_updates(
              ^^^^^^^^^^^^^^^^^^^^^^^^^^
    ...<9 lines>...
    )
    ^
  File "C:\Users\Alpha\AppData\Local\Programs\Python\Python313\Lib\site-packages\telegram\_bot.py", line 4780, in get_updates
    await self._post(
    ^^^^^^^^^^^^^^^^^
    ...<7 lines>...
    ),
    ^
  File "C:\Users\Alpha\AppData\Local\Programs\Python\Python313\Lib\site-packages\telegram\_bot.py", line 703, in _post
    return await self._do_post(
           ^^^^^^^^^^^^^^^^^^^^
    ...<6 lines>...
    )
    ^
  File "C:\Users\Alpha\AppData\Local\Programs\Python\Python313\Lib\site-packages\telegram\ext\_extbot.py", line 372, in _do_post
    return await super()._do_post(
           ^^^^^^^^^^^^^^^^^^^^^^^
    ...<6 lines>...
    )
    ^
  File "C:\Users\Alpha\AppData\Local\Programs\Python\Python313\Lib\site-packages\telegram\_bot.py", line 732, in _do_post
    result = await request.post(
             ^^^^^^^^^^^^^^^^^^^
    ...<6 lines>...
    )
    ^
  File "C:\Users\Alpha\AppData\Local\Programs\Python\Python313\Lib\site-packages\telegram\request\_baserequest.py", line 198, in post
    result = await self._request_wrapper(
             ^^^^^^^^^^^^^^^^^^^^^^^^^^^^
    ...<7 lines>...
    )
    ^
  File "C:\Users\Alpha\AppData\Local\Programs\Python\Python313\Lib\site-packages\telegram\request\_baserequest.py", line 375, in _request_wrapper
    raise exception
telegram.error.Conflict: Conflict: terminated by other getUpdates request; make sure that only one bot instance is running
2025-10-09 15:23:12 - telegram.ext.Application - ERROR - No error handlers are registered, logging exception.
Traceback (most recent call last):
  File "C:\Users\Alpha\AppData\Local\Programs\Python\Python313\Lib\site-packages\telegram\ext\_utils\networkloop.py", line 134, in network_retry_loop
    await do_action()
  File "C:\Users\Alpha\AppData\Local\Programs\Python\Python313\Lib\site-packages\telegram\ext\_utils\networkloop.py", line 127, in do_action
    action_cb_task.result()
    ~~~~~~~~~~~~~~~~~~~~~^^
  File "C:\Users\Alpha\AppData\Local\Programs\Python\Python313\Lib\site-packages\telegram\ext\_updater.py", line 340, in polling_action_cb
    updates = await self.bot.get_updates(
              ^^^^^^^^^^^^^^^^^^^^^^^^^^^
    ...<3 lines>...
    )
    ^
  File "C:\Users\Alpha\AppData\Local\Programs\Python\Python313\Lib\site-packages\telegram\ext\_extbot.py", line 676, in get_updates
    updates = await super().get_updates(
              ^^^^^^^^^^^^^^^^^^^^^^^^^^
    ...<9 lines>...
    )
    ^
  File "C:\Users\Alpha\AppData\Local\Programs\Python\Python313\Lib\site-packages\telegram\_bot.py", line 4780, in get_updates
    await self._post(
    ^^^^^^^^^^^^^^^^^
    ...<7 lines>...
    ),
    ^
  File "C:\Users\Alpha\AppData\Local\Programs\Python\Python313\Lib\site-packages\telegram\_bot.py", line 703, in _post
    return await self._do_post(
           ^^^^^^^^^^^^^^^^^^^^
    ...<6 lines>...
    )
    ^
  File "C:\Users\Alpha\AppData\Local\Programs\Python\Python313\Lib\site-packages\telegram\ext\_extbot.py", line 372, in _do_post
    return await super()._do_post(
           ^^^^^^^^^^^^^^^^^^^^^^^
    ...<6 lines>...
    )
    ^
  File "C:\Users\Alpha\AppData\Local\Programs\Python\Python313\Lib\site-packages\telegram\_bot.py", line 732, in _do_post
    result = await request.post(
             ^^^^^^^^^^^^^^^^^^^
    ...<6 lines>...
    )
    ^
  File "C:\Users\Alpha\AppData\Local\Programs\Python\Python313\Lib\site-packages\telegram\request\_baserequest.py", line 198, in post
    result = await self._request_wrapper(
             ^^^^^^^^^^^^^^^^^^^^^^^^^^^^
    ...<7 lines>...
    )
    ^
  File "C:\Users\Alpha\AppData\Local\Programs\Python\Python313\Lib\site-packages\telegram\request\_baserequest.py", line 375, in _request_wrapper
    raise exception
telegram.error.Conflict: Conflict: terminated by other getUpdates request; make sure that only one bot instance is running
2025-10-09 15:23:18 - telegram.ext.Application - ERROR - No error handlers are registered, logging exception.
Traceback (most recent call last):
  File "C:\Users\Alpha\AppData\Local\Programs\Python\Python313\Lib\site-packages\telegram\ext\_utils\networkloop.py", line 134, in network_retry_loop
    await do_action()
  File "C:\Users\Alpha\AppData\Local\Programs\Python\Python313\Lib\site-packages\telegram\ext\_utils\networkloop.py", line 127, in do_action
    action_cb_task.result()
    ~~~~~~~~~~~~~~~~~~~~~^^
  File "C:\Users\Alpha\AppData\Local\Programs\Python\Python313\Lib\site-packages\telegram\ext\_updater.py", line 340, in polling_action_cb
    updates = await self.bot.get_updates(
              ^^^^^^^^^^^^^^^^^^^^^^^^^^^
    ...<3 lines>...
    )
    ^
  File "C:\Users\Alpha\AppData\Local\Programs\Python\Python313\Lib\site-packages\telegram\ext\_extbot.py", line 676, in get_updates
    updates = await super().get_updates(
              ^^^^^^^^^^^^^^^^^^^^^^^^^^
    ...<9 lines>...
    )
    ^
  File "C:\Users\Alpha\AppData\Local\Programs\Python\Python313\Lib\site-packages\telegram\_bot.py", line 4780, in get_updates
    await self._post(
    ^^^^^^^^^^^^^^^^^
    ...<7 lines>...
    ),
    ^
  File "C:\Users\Alpha\AppData\Local\Programs\Python\Python313\Lib\site-packages\telegram\_bot.py", line 703, in _post
    return await self._do_post(
           ^^^^^^^^^^^^^^^^^^^^
    ...<6 lines>...
    )
    ^
  File "C:\Users\Alpha\AppData\Local\Programs\Python\Python313\Lib\site-packages\telegram\ext\_extbot.py", line 372, in _do_post
    return await super()._do_post(
           ^^^^^^^^^^^^^^^^^^^^^^^
    ...<6 lines>...
    )
    ^
  File "C:\Users\Alpha\AppData\Local\Programs\Python\Python313\Lib\site-packages\telegram\_bot.py", line 732, in _do_post
    result = await request.post(
             ^^^^^^^^^^^^^^^^^^^
    ...<6 lines>...
    )
    ^
  File "C:\Users\Alpha\AppData\Local\Programs\Python\Python313\Lib\site-packages\telegram\request\_baserequest.py", line 198, in post
    result = await self._request_wrapper(
             ^^^^^^^^^^^^^^^^^^^^^^^^^^^^
    ...<7 lines>...
    )
    ^
  File "C:\Users\Alpha\AppData\Local\Programs\Python\Python313\Lib\site-packages\telegram\request\_baserequest.py", line 375, in _request_wrapper
    raise exception
telegram.error.Conflict: Conflict: terminated by other getUpdates request; make sure that only one bot instance is running
2025-10-09 15:23:19 - telegram.ext - ERROR - Network Retry Loop (Polling Updates): Invalid token. Aborting retry loop.
Traceback (most recent call last):
  File "C:\Users\Alpha\AppData\Local\Programs\Python\Python313\Lib\site-packages\telegram\ext\_utils\networkloop.py", line 134, in network_retry_loop
    await do_action()
  File "C:\Users\Alpha\AppData\Local\Programs\Python\Python313\Lib\site-packages\telegram\ext\_utils\networkloop.py", line 127, in do_action
    action_cb_task.result()
    ~~~~~~~~~~~~~~~~~~~~~^^
  File "C:\Users\Alpha\AppData\Local\Programs\Python\Python313\Lib\site-packages\telegram\ext\_updater.py", line 340, in polling_action_cb
    updates = await self.bot.get_updates(
              ^^^^^^^^^^^^^^^^^^^^^^^^^^^
    ...<3 lines>...
    )
    ^
  File "C:\Users\Alpha\AppData\Local\Programs\Python\Python313\Lib\site-packages\telegram\ext\_extbot.py", line 676, in get_updates
    updates = await super().get_updates(
              ^^^^^^^^^^^^^^^^^^^^^^^^^^
    ...<9 lines>...
    )
    ^
  File "C:\Users\Alpha\AppData\Local\Programs\Python\Python313\Lib\site-packages\telegram\_bot.py", line 4780, in get_updates
    await self._post(
    ^^^^^^^^^^^^^^^^^
    ...<7 lines>...
    ),
    ^
  File "C:\Users\Alpha\AppData\Local\Programs\Python\Python313\Lib\site-packages\telegram\_bot.py", line 703, in _post
    return await self._do_post(
           ^^^^^^^^^^^^^^^^^^^^
    ...<6 lines>...
    )
    ^
  File "C:\Users\Alpha\AppData\Local\Programs\Python\Python313\Lib\site-packages\telegram\ext\_extbot.py", line 372, in _do_post
    return await super()._do_post(
           ^^^^^^^^^^^^^^^^^^^^^^^
    ...<6 lines>...
    )
    ^
  File "C:\Users\Alpha\AppData\Local\Programs\Python\Python313\Lib\site-packages\telegram\_bot.py", line 732, in _do_post
    result = await request.post(
             ^^^^^^^^^^^^^^^^^^^
    ...<6 lines>...
    )
    ^
  File "C:\Users\Alpha\AppData\Local\Programs\Python\Python313\Lib\site-packages\telegram\request\_baserequest.py", line 198, in post
    result = await self._request_wrapper(
             ^^^^^^^^^^^^^^^^^^^^^^^^^^^^
    ...<7 lines>...
    )
    ^
  File "C:\Users\Alpha\AppData\Local\Programs\Python\Python313\Lib\site-packages\telegram\request\_baserequest.py", line 375, in _request_wrapper
    raise exception
telegram.error.InvalidToken: Unauthorized
2025-10-09 17:13:24 - asyncio - ERROR - Task was destroyed but it is pending!
task: <Task pending name='Task-87' coro=<_render_timer_loop() done, defined at G:\FOR ALL BOTS\The_gap_2\src\handlers\task_handlers\task_timer.py:81> wait_for=<Future pending cb=[Task.task_wakeup()]>>
2025-10-09 17:13:24 - asyncio - ERROR - Task was destroyed but it is pending!
task: <Task cancelling name='Task-86' coro=<_time_tracker_loop() running at G:\FOR ALL BOTS\The_gap_2\src\handlers\task_handlers\task_timer.py:218> wait_for=<Future cancelled>>
2025-10-09 18:32:14 - asyncio - ERROR - Task was destroyed but it is pending!
task: <Task pending name='Task-17' coro=<_render_timer_loop() done, defined at G:\FOR ALL BOTS\The_gap_2\src\handlers\task_handlers\task_timer.py:38> wait_for=<Future pending cb=[Task.task_wakeup()]>>
