2025-10-09 15:21:25 - telegram.ext.Application - ERROR - No error handlers are registered, logging exception.
Traceback (most recent call last):
  File "C:\Users\Alpha\AppData\Local\Programs\Python\Python313\Lib\site-packages\telegram\ext\_utils\networkloop.py", line 134, in network_retry_loop
    await do_action()
  File "C:\Users\Alpha\AppData\Local\Programs\Python\Python313\Lib\site-packages\telegram\ext\_utils\networkloop.py", line 127, in do_action
    action_cb_task.result()
    ~~~~~~~~~~~~~~~~~~~~~^^
  File "C:\Users\Alpha\AppData\Local\Programs\Python\Python313\Lib\site-packages\telegram\ext\_updater.py", line 340, in polling_action_cb
    updates = await self.bot.get_updates(
              ^^^^^^^^^^^^^^^^^^^^^^^^^^^
    ...<3 lines>...
    )
    ^
  File "C:\Users\Alpha\AppData\Local\Programs\Python\Python313\Lib\site-packages\telegram\ext\_extbot.py", line 676, in get_updates
    updates = await super().get_updates(
              ^^^^^^^^^^^^^^^^^^^^^^^^^^
    ...<9 lines>...
    )
    ^
  File "C:\Users\Alpha\AppData\Local\Programs\Python\Python313\Lib\site-packages\telegram\_bot.py", line 4780, in get_updates
    await self._post(
    ^^^^^^^^^^^^^^^^^
    ...<7 lines>...
    ),
    ^
  File "C:\Users\Alpha\AppData\Local\Programs\Python\Python313\Lib\site-packages\telegram\_bot.py", line 703, in _post
    return await self._do_post(
           ^^^^^^^^^^^^^^^^^^^^
    ...<6 lines>...
    )
    ^
  File "C:\Users\Alpha\AppData\Local\Programs\Python\Python313\Lib\site-packages\telegram\ext\_extbot.py", line 372, in _do_post
    return await super()._do_post(
           ^^^^^^^^^^^^^^^^^^^^^^^
    ...<6 lines>...
    )
    ^
  File "C:\Users\Alpha\AppData\Local\Programs\Python\Python313\Lib\site-packages\telegram\_bot.py", line 732, in _do_post
    result = await request.post(
             ^^^^^^^^^^^^^^^^^^^
    ...<6 lines>...
    )
    ^
  File "C:\Users\Alpha\AppData\Local\Programs\Python\Python313\Lib\site-packages\telegram\request\_baserequest.py", line 198, in post
    result = await self._request_wrapper(
             ^^^^^^^^^^^^^^^^^^^^^^^^^^^^
    ...<7 lines>...
    )
    ^
  File "C:\Users\Alpha\AppData\Local\Programs\Python\Python313\Lib\site-packages\telegram\request\_baserequest.py", line 375, in _request_wrapper
    raise exception
telegram.error.Conflict: Conflict: terminated by other getUpdates request; make sure that only one bot instance is running
2025-10-09 15:21:29 - telegram.ext.Application - ERROR - No error handlers are registered, logging exception.
Traceback (most recent call last):
  File "C:\Users\Alpha\AppData\Local\Programs\Python\Python313\Lib\site-packages\telegram\ext\_utils\networkloop.py", line 134, in network_retry_loop
    await do_action()
  File "C:\Users\Alpha\AppData\Local\Programs\Python\Python313\Lib\site-packages\telegram\ext\_utils\networkloop.py", line 127, in do_action
    action_cb_task.result()
    ~~~~~~~~~~~~~~~~~~~~~^^
  File "C:\Users\Alpha\AppData\Local\Programs\Python\Python313\Lib\site-packages\telegram\ext\_updater.py", line 340, in polling_action_cb
    updates = await self.bot.get_updates(
              ^^^^^^^^^^^^^^^^^^^^^^^^^^^
    ...<3 lines>...
    )
    ^
  File "C:\Users\Alpha\AppData\Local\Programs\Python\Python313\Lib\site-packages\telegram\ext\_extbot.py", line 676, in get_updates
    updates = await super().get_updates(
              ^^^^^^^^^^^^^^^^^^^^^^^^^^
    ...<9 lines>...
    )
    ^
  File "C:\Users\Alpha\AppData\Local\Programs\Python\Python313\Lib\site-packages\telegram\_bot.py", line 4780, in get_updates
    await self._post(
    ^^^^^^^^^^^^^^^^^
    ...<7 lines>...
    ),
    ^
  File "C:\Users\Alpha\AppData\Local\Programs\Python\Python313\Lib\site-packages\telegram\_bot.py", line 703, in _post
    return await self._do_post(
           ^^^^^^^^^^^^^^^^^^^^
    ...<6 lines>...
    )
    ^
  File "C:\Users\Alpha\AppData\Local\Programs\Python\Python313\Lib\site-packages\telegram\ext\_extbot.py", line 372, in _do_post
    return await super()._do_post(
           ^^^^^^^^^^^^^^^^^^^^^^^
    ...<6 lines>...
    )
    ^
  File "C:\Users\Alpha\AppData\Local\Programs\Python\Python313\Lib\site-packages\telegram\_bot.py", line 732, in _do_post
    result = await request.post(
             ^^^^^^^^^^^^^^^^^^^
    ...<6 lines>...
    )
    ^
  File "C:\Users\Alpha\AppData\Local\Programs\Python\Python313\Lib\site-packages\telegram\request\_baserequest.py", line 198, in post
    result = await self._request_wrapper(
             ^^^^^^^^^^^^^^^^^^^^^^^^^^^^
    ...<7 lines>...
    )
    ^
  File "C:\Users\Alpha\AppData\Local\Programs\Python\Python313\Lib\site-packages\telegram\request\_baserequest.py", line 375, in _request_wrapper
    raise exception
telegram.error.Conflict: Conflict: terminated by other getUpdates request; make sure that only one bot instance is running
2025-10-09 15:21:30 - telegram.ext.Application - ERROR - No error handlers are registered, logging exception.
Traceback (most recent call last):
  File "C:\Users\Alpha\AppData\Local\Programs\Python\Python313\Lib\site-packages\telegram\ext\_utils\networkloop.py", line 134, in network_retry_loop
    await do_action()
  File "C:\Users\Alpha\AppData\Local\Programs\Python\Python313\Lib\site-packages\telegram\ext\_utils\networkloop.py", line 127, in do_action
    action_cb_task.result()
    ~~~~~~~~~~~~~~~~~~~~~^^
  File "C:\Users\Alpha\AppData\Local\Programs\Python\Python313\Lib\site-packages\telegram\ext\_updater.py", line 340, in polling_action_cb
    updates = await self.bot.get_updates(
              ^^^^^^^^^^^^^^^^^^^^^^^^^^^
    ...<3 lines>...
    )
    ^
  File "C:\Users\Alpha\AppData\Local\Programs\Python\Python313\Lib\site-packages\telegram\ext\_extbot.py", line 676, in get_updates
    updates = await super().get_updates(
              ^^^^^^^^^^^^^^^^^^^^^^^^^^
    ...<9 lines>...
    )
    ^
  File "C:\Users\Alpha\AppData\Local\Programs\Python\Python313\Lib\site-packages\telegram\_bot.py", line 4780, in get_updates
    await self._post(
    ^^^^^^^^^^^^^^^^^
    ...<7 lines>...
    ),
    ^
  File "C:\Users\Alpha\AppData\Local\Programs\Python\Python313\Lib\site-packages\telegram\_bot.py", line 703, in _post
    return await self._do_post(
           ^^^^^^^^^^^^^^^^^^^^
    ...<6 lines>...
    )
    ^
  File "C:\Users\Alpha\AppData\Local\Programs\Python\Python313\Lib\site-packages\telegram\ext\_extbot.py", line 372, in _do_post
    return await super()._do_post(
           ^^^^^^^^^^^^^^^^^^^^^^^
    ...<6 lines>...
    )
    ^
  File "C:\Users\Alpha\AppData\Local\Programs\Python\Python313\Lib\site-packages\telegram\_bot.py", line 732, in _do_post
    result = await request.post(
             ^^^^^^^^^^^^^^^^^^^
    ...<6 lines>...
    )
    ^
  File "C:\Users\Alpha\AppData\Local\Programs\Python\Python313\Lib\site-packages\telegram\request\_baserequest.py", line 198, in post
    result = await self._request_wrapper(
             ^^^^^^^^^^^^^^^^^^^^^^^^^^^^
    ...<7 lines>...
    )
    ^
  File "C:\Users\Alpha\AppData\Local\Programs\Python\Python313\Lib\site-packages\telegram\request\_baserequest.py", line 375, in _request_wrapper
    raise exception
telegram.error.Conflict: Conflict: terminated by other getUpdates request; make sure that only one bot instance is running
2025-10-09 15:21:36 - telegram.ext.Application - ERROR - No error handlers are registered, logging exception.
Traceback (most recent call last):
  File "C:\Users\Alpha\AppData\Local\Programs\Python\Python313\Lib\site-packages\telegram\ext\_utils\networkloop.py", line 134, in network_retry_loop
    await do_action()
  File "C:\Users\Alpha\AppData\Local\Programs\Python\Python313\Lib\site-packages\telegram\ext\_utils\networkloop.py", line 127, in do_action
    action_cb_task.result()
    ~~~~~~~~~~~~~~~~~~~~~^^
  File "C:\Users\Alpha\AppData\Local\Programs\Python\Python313\Lib\site-packages\telegram\ext\_updater.py", line 340, in polling_action_cb
    updates = await self.bot.get_updates(
              ^^^^^^^^^^^^^^^^^^^^^^^^^^^
    ...<3 lines>...
    )
    ^
  File "C:\Users\Alpha\AppData\Local\Programs\Python\Python313\Lib\site-packages\telegram\ext\_extbot.py", line 676, in get_updates
    updates = await super().get_updates(
              ^^^^^^^^^^^^^^^^^^^^^^^^^^
    ...<9 lines>...
    )
    ^
  File "C:\Users\Alpha\AppData\Local\Programs\Python\Python313\Lib\site-packages\telegram\_bot.py", line 4780, in get_updates
    await self._post(
    ^^^^^^^^^^^^^^^^^
    ...<7 lines>...
    ),
    ^
  File "C:\Users\Alpha\AppData\Local\Programs\Python\Python313\Lib\site-packages\telegram\_bot.py", line 703, in _post
    return await self._do_post(
           ^^^^^^^^^^^^^^^^^^^^
    ...<6 lines>...
    )
    ^
  File "C:\Users\Alpha\AppData\Local\Programs\Python\Python313\Lib\site-packages\telegram\ext\_extbot.py", line 372, in _do_post
    return await super()._do_post(
           ^^^^^^^^^^^^^^^^^^^^^^^
    ...<6 lines>...
    )
    ^
  File "C:\Users\Alpha\AppData\Local\Programs\Python\Python313\Lib\site-packages\telegram\_bot.py", line 732, in _do_post
    result = await request.post(
             ^^^^^^^^^^^^^^^^^^^
    ...<6 lines>...
    )
    ^
  File "C:\Users\Alpha\AppData\Local\Programs\Python\Python313\Lib\site-packages\telegram\request\_baserequest.py", line 198, in post
    result = await self._request_wrapper(
             ^^^^^^^^^^^^^^^^^^^^^^^^^^^^
    ...<7 lines>...
    )
    ^
  File "C:\Users\Alpha\AppData\Local\Programs\Python\Python313\Lib\site-packages\telegram\request\_baserequest.py", line 375, in _request_wrapper
    raise exception
telegram.error.Conflict: Conflict: terminated by other getUpdates request; make sure that only one bot instance is running
2025-10-09 15:23:12 - telegram.ext.Application - ERROR - No error handlers are registered, logging exception.
Traceback (most recent call last):
  File "C:\Users\Alpha\AppData\Local\Programs\Python\Python313\Lib\site-packages\telegram\ext\_utils\networkloop.py", line 134, in network_retry_loop
    await do_action()
  File "C:\Users\Alpha\AppData\Local\Programs\Python\Python313\Lib\site-packages\telegram\ext\_utils\networkloop.py", line 127, in do_action
    action_cb_task.result()
    ~~~~~~~~~~~~~~~~~~~~~^^
  File "C:\Users\Alpha\AppData\Local\Programs\Python\Python313\Lib\site-packages\telegram\ext\_updater.py", line 340, in polling_action_cb
    updates = await self.bot.get_updates(
              ^^^^^^^^^^^^^^^^^^^^^^^^^^^
    ...<3 lines>...
    )
    ^
  File "C:\Users\Alpha\AppData\Local\Programs\Python\Python313\Lib\site-packages\telegram\ext\_extbot.py", line 676, in get_updates
    updates = await super().get_updates(
              ^^^^^^^^^^^^^^^^^^^^^^^^^^
    ...<9 lines>...
    )
    ^
  File "C:\Users\Alpha\AppData\Local\Programs\Python\Python313\Lib\site-packages\telegram\_bot.py", line 4780, in get_updates
    await self._post(
    ^^^^^^^^^^^^^^^^^
    ...<7 lines>...
    ),
    ^
  File "C:\Users\Alpha\AppData\Local\Programs\Python\Python313\Lib\site-packages\telegram\_bot.py", line 703, in _post
    return await self._do_post(
           ^^^^^^^^^^^^^^^^^^^^
    ...<6 lines>...
    )
    ^
  File "C:\Users\Alpha\AppData\Local\Programs\Python\Python313\Lib\site-packages\telegram\ext\_extbot.py", line 372, in _do_post
    return await super()._do_post(
           ^^^^^^^^^^^^^^^^^^^^^^^
    ...<6 lines>...
    )
    ^
  File "C:\Users\Alpha\AppData\Local\Programs\Python\Python313\Lib\site-packages\telegram\_bot.py", line 732, in _do_post
    result = await request.post(
             ^^^^^^^^^^^^^^^^^^^
    ...<6 lines>...
    )
    ^
  File "C:\Users\Alpha\AppData\Local\Programs\Python\Python313\Lib\site-packages\telegram\request\_baserequest.py", line 198, in post
    result = await self._request_wrapper(
             ^^^^^^^^^^^^^^^^^^^^^^^^^^^^
    ...<7 lines>...
    )
    ^
  File "C:\Users\Alpha\AppData\Local\Programs\Python\Python313\Lib\site-packages\telegram\request\_baserequest.py", line 375, in _request_wrapper
    raise exception
telegram.error.Conflict: Conflict: terminated by other getUpdates request; make sure that only one bot instance is running
2025-10-09 15:23:18 - telegram.ext.Application - ERROR - No error handlers are registered, logging exception.
Traceback (most recent call last):
  File "C:\Users\Alpha\AppData\Local\Programs\Python\Python313\Lib\site-packages\telegram\ext\_utils\networkloop.py", line 134, in network_retry_loop
    await do_action()
  File "C:\Users\Alpha\AppData\Local\Programs\Python\Python313\Lib\site-packages\telegram\ext\_utils\networkloop.py", line 127, in do_action
    action_cb_task.result()
    ~~~~~~~~~~~~~~~~~~~~~^^
  File "C:\Users\Alpha\AppData\Local\Programs\Python\Python313\Lib\site-packages\telegram\ext\_updater.py", line 340, in polling_action_cb
    updates = await self.bot.get_updates(
              ^^^^^^^^^^^^^^^^^^^^^^^^^^^
    ...<3 lines>...
    )
    ^
  File "C:\Users\Alpha\AppData\Local\Programs\Python\Python313\Lib\site-packages\telegram\ext\_extbot.py", line 676, in get_updates
    updates = await super().get_updates(
              ^^^^^^^^^^^^^^^^^^^^^^^^^^
    ...<9 lines>...
    )
    ^
  File "C:\Users\Alpha\AppData\Local\Programs\Python\Python313\Lib\site-packages\telegram\_bot.py", line 4780, in get_updates
    await self._post(
    ^^^^^^^^^^^^^^^^^
    ...<7 lines>...
    ),
    ^
  File "C:\Users\Alpha\AppData\Local\Programs\Python\Python313\Lib\site-packages\telegram\_bot.py", line 703, in _post
    return await self._do_post(
           ^^^^^^^^^^^^^^^^^^^^
    ...<6 lines>...
    )
    ^
  File "C:\Users\Alpha\AppData\Local\Programs\Python\Python313\Lib\site-packages\telegram\ext\_extbot.py", line 372, in _do_post
    return await super()._do_post(
           ^^^^^^^^^^^^^^^^^^^^^^^
    ...<6 lines>...
    )
    ^
  File "C:\Users\Alpha\AppData\Local\Programs\Python\Python313\Lib\site-packages\telegram\_bot.py", line 732, in _do_post
    result = await request.post(
             ^^^^^^^^^^^^^^^^^^^
    ...<6 lines>...
    )
    ^
  File "C:\Users\Alpha\AppData\Local\Programs\Python\Python313\Lib\site-packages\telegram\request\_baserequest.py", line 198, in post
    result = await self._request_wrapper(
             ^^^^^^^^^^^^^^^^^^^^^^^^^^^^
    ...<7 lines>...
    )
    ^
  File "C:\Users\Alpha\AppData\Local\Programs\Python\Python313\Lib\site-packages\telegram\request\_baserequest.py", line 375, in _request_wrapper
    raise exception
telegram.error.Conflict: Conflict: terminated by other getUpdates request; make sure that only one bot instance is running
2025-10-09 15:23:19 - telegram.ext - ERROR - Network Retry Loop (Polling Updates): Invalid token. Aborting retry loop.
Traceback (most recent call last):
  File "C:\Users\Alpha\AppData\Local\Programs\Python\Python313\Lib\site-packages\telegram\ext\_utils\networkloop.py", line 134, in network_retry_loop
    await do_action()
  File "C:\Users\Alpha\AppData\Local\Programs\Python\Python313\Lib\site-packages\telegram\ext\_utils\networkloop.py", line 127, in do_action
    action_cb_task.result()
    ~~~~~~~~~~~~~~~~~~~~~^^
  File "C:\Users\Alpha\AppData\Local\Programs\Python\Python313\Lib\site-packages\telegram\ext\_updater.py", line 340, in polling_action_cb
    updates = await self.bot.get_updates(
              ^^^^^^^^^^^^^^^^^^^^^^^^^^^
    ...<3 lines>...
    )
    ^
  File "C:\Users\Alpha\AppData\Local\Programs\Python\Python313\Lib\site-packages\telegram\ext\_extbot.py", line 676, in get_updates
    updates = await super().get_updates(
              ^^^^^^^^^^^^^^^^^^^^^^^^^^
    ...<9 lines>...
    )
    ^
  File "C:\Users\Alpha\AppData\Local\Programs\Python\Python313\Lib\site-packages\telegram\_bot.py", line 4780, in get_updates
    await self._post(
    ^^^^^^^^^^^^^^^^^
    ...<7 lines>...
    ),
    ^
  File "C:\Users\Alpha\AppData\Local\Programs\Python\Python313\Lib\site-packages\telegram\_bot.py", line 703, in _post
    return await self._do_post(
           ^^^^^^^^^^^^^^^^^^^^
    ...<6 lines>...
    )
    ^
  File "C:\Users\Alpha\AppData\Local\Programs\Python\Python313\Lib\site-packages\telegram\ext\_extbot.py", line 372, in _do_post
    return await super()._do_post(
           ^^^^^^^^^^^^^^^^^^^^^^^
    ...<6 lines>...
    )
    ^
  File "C:\Users\Alpha\AppData\Local\Programs\Python\Python313\Lib\site-packages\telegram\_bot.py", line 732, in _do_post
    result = await request.post(
             ^^^^^^^^^^^^^^^^^^^
    ...<6 lines>...
    )
    ^
  File "C:\Users\Alpha\AppData\Local\Programs\Python\Python313\Lib\site-packages\telegram\request\_baserequest.py", line 198, in post
    result = await self._request_wrapper(
             ^^^^^^^^^^^^^^^^^^^^^^^^^^^^
    ...<7 lines>...
    )
    ^
  File "C:\Users\Alpha\AppData\Local\Programs\Python\Python313\Lib\site-packages\telegram\request\_baserequest.py", line 375, in _request_wrapper
    raise exception
telegram.error.InvalidToken: Unauthorized
2025-10-09 17:13:24 - asyncio - ERROR - Task was destroyed but it is pending!
task: <Task pending name='Task-87' coro=<_render_timer_loop() done, defined at G:\FOR ALL BOTS\The_gap_2\src\handlers\task_handlers\task_timer.py:81> wait_for=<Future pending cb=[Task.task_wakeup()]>>
2025-10-09 17:13:24 - asyncio - ERROR - Task was destroyed but it is pending!
task: <Task cancelling name='Task-86' coro=<_time_tracker_loop() running at G:\FOR ALL BOTS\The_gap_2\src\handlers\task_handlers\task_timer.py:218> wait_for=<Future cancelled>>
2025-10-09 18:32:14 - asyncio - ERROR - Task was destroyed but it is pending!
task: <Task pending name='Task-17' coro=<_render_timer_loop() done, defined at G:\FOR ALL BOTS\The_gap_2\src\handlers\task_handlers\task_timer.py:38> wait_for=<Future pending cb=[Task.task_wakeup()]>>
2025-10-09 20:25:41 - asyncio - ERROR - Task was destroyed but it is pending!
task: <Task pending name='Task-1327' coro=<_render_timer_loop() running at G:\FOR ALL BOTS\The_gap_2\src\handlers\task_handlers\task_timer.py:140> wait_for=<Future pending cb=[Task.task_wakeup()]>>
2025-10-09 20:25:41 - asyncio - ERROR - Task was destroyed but it is pending!
task: <Task pending name='Task-1273' coro=<_render_timer_loop() running at G:\FOR ALL BOTS\The_gap_2\src\handlers\task_handlers\task_timer.py:140> wait_for=<Future pending cb=[Task.task_wakeup()]>>
2025-10-09 20:32:04 - telegram.ext.Application - ERROR - No error handlers are registered, logging exception.
Traceback (most recent call last):
  File "C:\Users\Alpha\AppData\Local\Programs\Python\Python313\Lib\site-packages\telegram\ext\_application.py", line 1315, in process_update
    await coroutine
  File "C:\Users\Alpha\AppData\Local\Programs\Python\Python313\Lib\site-packages\telegram\ext\_handlers\basehandler.py", line 159, in handle_update
    return await self.callback(update, context)
           ^^^^^^^^^^^^^^^^^^^^^^^^^^^^^^^^^^^^
  File "G:\FOR ALL BOTS\The_gap_2\src\handlers\task_handlers\task_execution.py", line 218, in show_task
    from ...utils.message_formatter import format_task_message
  File "G:\FOR ALL BOTS\The_gap_2\src\utils\message_formatter.py", line 4, in <module>
    from .time_utils import seconds_to_hms, hms_to_seconds, calculate_remaining_time
ImportError: cannot import name 'hms_to_seconds' from 'src.utils.time_utils' (G:\FOR ALL BOTS\The_gap_2\src\utils\time_utils.py)
2025-10-09 20:34:19 - asyncio - ERROR - Task was destroyed but it is pending!
task: <Task pending name='Task-23' coro=<_render_timer_loop() done, defined at G:\FOR ALL BOTS\The_gap_2\src\handlers\task_handlers\task_timer.py:38> wait_for=<Future pending cb=[Task.task_wakeup()]>>
2025-10-09 21:09:41 - telegram.ext.Application - ERROR - No error handlers are registered, logging exception.
Traceback (most recent call last):
  File "G:\FOR ALL BOTS\The_gap_2\src\scheduler\task_scheduler.py", line 46, in schedule_tasks_from_rules
    print(f"🔍 Найдено заданий: {len(schedule_df)}")
                                 ~~~^^^^^^^^^^^^^
TypeError: object of type 'AttributeError' has no len()

During handling of the above exception, another exception occurred:

Traceback (most recent call last):
  File "C:\Users\Alpha\AppData\Local\Programs\Python\Python313\Lib\site-packages\telegram\ext\_jobqueue.py", line 998, in _run
    await self.callback(context)
  File "G:\FOR ALL BOTS\The_gap_2\src\scheduler\task_scheduler.py", line 445, in schedule_tasks_from_rules
OSError: [Errno 22] Invalid argument
